{"trial_id": "1", "hyperparameters": {"space": [{"class_name": "Float", "config": {"name": "dropout", "default": 0.3, "conditions": [], "min_value": 0.3, "max_value": 0.7, "step": 0.1, "sampling": "linear"}}, {"class_name": "Choice", "config": {"name": "learning_rate", "default": 0.0001, "conditions": [], "values": [0.0001, 0.0003, 0.001], "ordered": true}}], "values": {"dropout": 0.6000000000000001, "learning_rate": 0.001}}, "metrics": {"metrics": {}}, "score": null, "best_step": 0, "status": "FAILED", "message": "Traceback (most recent call last):\n  File \"/home/ryan-bulger/.local/lib/python3.13/site-packages/keras_tuner/src/engine/base_tuner.py\", line 274, in _try_run_and_update_trial\n    self._run_and_update_trial(trial, *fit_args, **fit_kwargs)\n    ~~~~~~~~~~~~~~~~~~~~~~~~~~^^^^^^^^^^^^^^^^^^^^^^^^^^^^^^^^\n  File \"/home/ryan-bulger/.local/lib/python3.13/site-packages/keras_tuner/src/engine/base_tuner.py\", line 239, in _run_and_update_trial\n    results = self.run_trial(trial, *fit_args, **fit_kwargs)\n  File \"/home/ryan-bulger/.local/lib/python3.13/site-packages/keras_tuner/src/engine/tuner.py\", line 314, in run_trial\n    obj_value = self._build_and_fit_model(trial, *args, **copied_kwargs)\n  File \"/home/ryan-bulger/.local/lib/python3.13/site-packages/keras_tuner/src/engine/tuner.py\", line 233, in _build_and_fit_model\n    results = self.hypermodel.fit(hp, model, *args, **kwargs)\n  File \"/home/ryan-bulger/.local/lib/python3.13/site-packages/keras_tuner/src/engine/hypermodel.py\", line 149, in fit\n    return model.fit(*args, **kwargs)\n           ~~~~~~~~~^^^^^^^^^^^^^^^^^\n  File \"/home/ryan-bulger/.local/lib/python3.13/site-packages/keras/src/utils/traceback_utils.py\", line 122, in error_handler\n    raise e.with_traceback(filtered_tb) from None\n  File \"/home/ryan-bulger/.local/lib/python3.13/site-packages/tensorflow/python/eager/execute.py\", line 59, in quick_execute\n    except TypeError as e:\n    ...<5 lines>...\n      raise e\ntensorflow.python.framework.errors_impl.ResourceExhaustedError: Graph execution error:\n\nDetected at node functional_1/conv2d_1/Relu defined at (most recent call last):\n  File \"<frozen runpy>\", line 198, in _run_module_as_main\n\n  File \"<frozen runpy>\", line 88, in _run_code\n\n  File \"/home/ryan-bulger/.local/lib/python3.13/site-packages/ipykernel_launcher.py\", line 18, in <module>\n\n  File \"/home/ryan-bulger/.local/lib/python3.13/site-packages/traitlets/config/application.py\", line 1075, in launch_instance\n\n  File \"/home/ryan-bulger/.local/lib/python3.13/site-packages/ipykernel/kernelapp.py\", line 739, in start\n\n  File \"/home/ryan-bulger/.local/lib/python3.13/site-packages/tornado/platform/asyncio.py\", line 211, in start\n\n  File \"/usr/local/lib/python3.13/asyncio/base_events.py\", line 683, in run_forever\n\n  File \"/usr/local/lib/python3.13/asyncio/base_events.py\", line 2042, in _run_once\n\n  File \"/usr/local/lib/python3.13/asyncio/events.py\", line 89, in _run\n\n  File \"/home/ryan-bulger/.local/lib/python3.13/site-packages/ipykernel/kernelbase.py\", line 545, in dispatch_queue\n\n  File \"/home/ryan-bulger/.local/lib/python3.13/site-packages/ipykernel/kernelbase.py\", line 534, in process_one\n\n  File \"/home/ryan-bulger/.local/lib/python3.13/site-packages/ipykernel/kernelbase.py\", line 437, in dispatch_shell\n\n  File \"/home/ryan-bulger/.local/lib/python3.13/site-packages/ipykernel/ipkernel.py\", line 362, in execute_request\n\n  File \"/home/ryan-bulger/.local/lib/python3.13/site-packages/ipykernel/kernelbase.py\", line 778, in execute_request\n\n  File \"/home/ryan-bulger/.local/lib/python3.13/site-packages/ipykernel/ipkernel.py\", line 449, in do_execute\n\n  File \"/home/ryan-bulger/.local/lib/python3.13/site-packages/ipykernel/zmqshell.py\", line 549, in run_cell\n\n  File \"/home/ryan-bulger/.local/lib/python3.13/site-packages/IPython/core/interactiveshell.py\", line 3116, in run_cell\n\n  File \"/home/ryan-bulger/.local/lib/python3.13/site-packages/IPython/core/interactiveshell.py\", line 3171, in _run_cell\n\n  File \"/home/ryan-bulger/.local/lib/python3.13/site-packages/IPython/core/async_helpers.py\", line 128, in _pseudo_sync_runner\n\n  File \"/home/ryan-bulger/.local/lib/python3.13/site-packages/IPython/core/interactiveshell.py\", line 3394, in run_cell_async\n\n  File \"/home/ryan-bulger/.local/lib/python3.13/site-packages/IPython/core/interactiveshell.py\", line 3639, in run_ast_nodes\n\n  File \"/home/ryan-bulger/.local/lib/python3.13/site-packages/IPython/core/interactiveshell.py\", line 3699, in run_code\n\n  File \"/tmp/ipykernel_7203/3195196871.py\", line 23, in <module>\n\n  File \"/home/ryan-bulger/.local/lib/python3.13/site-packages/keras_tuner/src/engine/base_tuner.py\", line 234, in search\n\n  File \"/home/ryan-bulger/.local/lib/python3.13/site-packages/keras_tuner/src/engine/base_tuner.py\", line 274, in _try_run_and_update_trial\n\n  File \"/home/ryan-bulger/.local/lib/python3.13/site-packages/keras_tuner/src/engine/base_tuner.py\", line 239, in _run_and_update_trial\n\n  File \"/home/ryan-bulger/.local/lib/python3.13/site-packages/keras_tuner/src/engine/tuner.py\", line 314, in run_trial\n\n  File \"/home/ryan-bulger/.local/lib/python3.13/site-packages/keras_tuner/src/engine/tuner.py\", line 233, in _build_and_fit_model\n\n  File \"/home/ryan-bulger/.local/lib/python3.13/site-packages/keras_tuner/src/engine/hypermodel.py\", line 149, in fit\n\n  File \"/home/ryan-bulger/.local/lib/python3.13/site-packages/keras/src/utils/traceback_utils.py\", line 117, in error_handler\n\n  File \"/home/ryan-bulger/.local/lib/python3.13/site-packages/keras/src/backend/tensorflow/trainer.py\", line 377, in fit\n\n  File \"/home/ryan-bulger/.local/lib/python3.13/site-packages/keras/src/backend/tensorflow/trainer.py\", line 220, in function\n\n  File \"/home/ryan-bulger/.local/lib/python3.13/site-packages/keras/src/backend/tensorflow/trainer.py\", line 133, in multi_step_on_iterator\n\n  File \"/home/ryan-bulger/.local/lib/python3.13/site-packages/keras/src/backend/tensorflow/trainer.py\", line 114, in one_step_on_data\n\n  File \"/home/ryan-bulger/.local/lib/python3.13/site-packages/keras/src/backend/tensorflow/trainer.py\", line 58, in train_step\n\n  File \"/home/ryan-bulger/.local/lib/python3.13/site-packages/keras/src/utils/traceback_utils.py\", line 117, in error_handler\n\n  File \"/home/ryan-bulger/.local/lib/python3.13/site-packages/keras/src/layers/layer.py\", line 941, in __call__\n\n  File \"/home/ryan-bulger/.local/lib/python3.13/site-packages/keras/src/utils/traceback_utils.py\", line 117, in error_handler\n\n  File \"/home/ryan-bulger/.local/lib/python3.13/site-packages/keras/src/ops/operation.py\", line 59, in __call__\n\n  File \"/home/ryan-bulger/.local/lib/python3.13/site-packages/keras/src/utils/traceback_utils.py\", line 156, in error_handler\n\n  File \"/home/ryan-bulger/.local/lib/python3.13/site-packages/keras/src/models/functional.py\", line 183, in call\n\n  File \"/home/ryan-bulger/.local/lib/python3.13/site-packages/keras/src/ops/function.py\", line 206, in _run_through_graph\n\n  File \"/home/ryan-bulger/.local/lib/python3.13/site-packages/keras/src/models/functional.py\", line 644, in call\n\n  File \"/home/ryan-bulger/.local/lib/python3.13/site-packages/keras/src/utils/traceback_utils.py\", line 117, in error_handler\n\n  File \"/home/ryan-bulger/.local/lib/python3.13/site-packages/keras/src/layers/layer.py\", line 941, in __call__\n\n  File \"/home/ryan-bulger/.local/lib/python3.13/site-packages/keras/src/utils/traceback_utils.py\", line 117, in error_handler\n\n  File \"/home/ryan-bulger/.local/lib/python3.13/site-packages/keras/src/ops/operation.py\", line 59, in __call__\n\n  File \"/home/ryan-bulger/.local/lib/python3.13/site-packages/keras/src/utils/traceback_utils.py\", line 156, in error_handler\n\n  File \"/home/ryan-bulger/.local/lib/python3.13/site-packages/keras/src/layers/convolutional/base_conv.py\", line 263, in call\n\n  File \"/home/ryan-bulger/.local/lib/python3.13/site-packages/keras/src/activations/activations.py\", line 47, in relu\n\n  File \"/home/ryan-bulger/.local/lib/python3.13/site-packages/keras/src/activations/activations.py\", line 101, in static_call\n\n  File \"/home/ryan-bulger/.local/lib/python3.13/site-packages/keras/src/backend/tensorflow/nn.py\", line 15, in relu\n\nOOM when allocating tensor with shape[5000,32,94,94] and type float on /job:localhost/replica:0/task:0/device:GPU:0 by allocator GPU_0_bfc\n\t [[{{node functional_1/conv2d_1/Relu}}]]\nHint: If you want to see a list of allocated tensors when OOM happens, add report_tensor_allocations_upon_oom to RunOptions for current allocation info. This isn't available when running in Eager mode.\n [Op:__inference_multi_step_on_iterator_17055]\n"}